<sdf version='1.6'>
  <world name='default'>
    <light name='sun' type='directional'>
      <cast_shadows>1</cast_shadows>
      <pose frame=''>0 0 10 0 -0 0</pose>
      <diffuse>0.8 0.8 0.8 1</diffuse>
      <specular>0.2 0.2 0.2 1</specular>
      <attenuation>
        <range>1000</range>
        <constant>0.9</constant>
        <linear>0.01</linear>
        <quadratic>0.001</quadratic>
      </attenuation>
      <direction>-0.5 0.1 -0.9</direction>
    </light>
    <model name='ground_plane'>
      <static>1</static>
      <link name='link'>
        <collision name='collision'>
          <geometry>
            <plane>
              <normal>0 0 1</normal>
              <size>100 100</size>
            </plane>
          </geometry>
          <surface>
            <friction>
              <ode>
                <mu>100</mu>
                <mu2>50</mu2>
              </ode>
              <torsional>
                <ode/>
              </torsional>
            </friction>
            <contact>
              <ode/>
            </contact>
            <bounce/>
          </surface>
          <max_contacts>10</max_contacts>
        </collision>
        <visual name='visual'>
          <cast_shadows>0</cast_shadows>
          <geometry>
            <plane>
              <normal>0 0 1</normal>
              <size>100 100</size>
            </plane>
          </geometry>
          <material>
            <script>
              <uri>file://media/materials/scripts/gazebo.material</uri>
              <name>Gazebo/Grey</name>
            </script>
          </material>
        </visual>
        <self_collide>0</self_collide>
        <enable_wind>0</enable_wind>
        <kinematic>0</kinematic>
      </link>
    </model>
    <gravity>0 0 -9.8</gravity>
    <magnetic_field>6e-06 2.3e-05 -4.2e-05</magnetic_field>
    <atmosphere type='adiabatic'/>
    <physics name='default_physics' default='0' type='ode'>
      <max_step_size>0.001</max_step_size>
      <real_time_factor>1</real_time_factor>
      <real_time_update_rate>1000</real_time_update_rate>
    </physics>
    <scene>
      <ambient>0.4 0.4 0.4 1</ambient>
      <background>0.7 0.7 0.7 1</background>
      <shadows>1</shadows>
    </scene>
    <audio>
      <device>default</device>
    </audio>
    <wind/>
    <spherical_coordinates>
      <surface_model>EARTH_WGS84</surface_model>
      <latitude_deg>0</latitude_deg>
      <longitude_deg>0</longitude_deg>
      <elevation>0</elevation>
      <heading_deg>0</heading_deg>
    </spherical_coordinates>
    <model name='fake_car'>
      <link name='base_link'>
        <pose frame=''>0 0 0 0 -0 0</pose>
        <inertial>
          <pose frame=''>0.170793 0 0.059771 0 -0 0</pose>
          <mass>2.61001</mass>
          <inertia>
            <ixx>0.0293588</ixx>
            <ixy>0</ixy>
            <ixz>-0.000102427</ixz>
            <iyy>0.0640857</iyy>
            <iyz>0</iyz>
            <izz>0.0640496</izz>
          </inertia>
        </inertial>
        <collision name='base_link_collision'>
          <pose frame=''>0 0 0.1 0 -0 0</pose>
          <geometry>
            <cylinder>
              <length>0.2</length>
              <radius>0.01</radius>
            </cylinder>
          </geometry>
          <surface>
            <contact>
              <ode/>
            </contact>
            <friction>
              <ode/>
              <torsional>
                <ode/>
              </torsional>
            </friction>
            <bounce/>
          </surface>
          <max_contacts>10</max_contacts>
        </collision>
        <collision name='base_link_fixed_joint_lump__chassis_link_collision_1'>
          <pose frame=''>0.17145 0 0.06 0 -0 0</pose>
          <geometry>
            <box>
              <size>0.3429 0.25 0.06</size>
            </box>
          </geometry>
          <max_contacts>10</max_contacts>
          <surface>
            <contact>
              <ode/>
            </contact>
            <bounce/>
            <friction>
              <torsional>
                <ode/>
              </torsional>
              <ode/>
            </friction>
          </surface>
        </collision>
        <collision name='base_link_fixed_joint_lump__laser_scanner_link_collision_2'>
          <pose frame=''>0.1397 0 0.2159 0 -0 0</pose>
          <geometry>
            <box>
              <size>0.127 0.1016 0.0508</size>
            </box>
          </geometry>
          <surface>
            <contact>
              <ode/>
            </contact>
            <friction>
              <ode/>
              <torsional>
                <ode/>
              </torsional>
            </friction>
            <bounce/>
          </surface>
          <max_contacts>10</max_contacts>
        </collision>
        <visual name='base_link_visual'>
          <pose frame=''>0 0 0.1 0 -0 0</pose>
          <geometry>
            <cylinder>
              <length>0.2</length>
              <radius>0.01</radius>
            </cylinder>
          </geometry>
          <material>
            <script>
              <uri>__default__</uri>
              <name>__default__</name>
            </script>
          </material>
        </visual>
        <visual name='base_link_fixed_joint_lump__chassis_link_visual_1'>
          <pose frame=''>0.17145 0 0.06 0 -0 0</pose>
          <geometry>
            <box>
              <size>0.3429 0.25 0.06</size>
            </box>
          </geometry>
        </visual>
        <visual name='base_link_fixed_joint_lump__laser_scanner_link_visual_2'>
          <pose frame=''>0.1397 0 0.2159 0 -0 0</pose>
          <geometry>
            <box>
              <size>0.127 0.1016 0.0508</size>
            </box>
          </geometry>
          <material>
            <script>
              <uri>__default__</uri>
              <name>__default__</name>
            </script>
          </material>
        </visual>
        <velocity_decay>
          <linear>7e-05</linear>
          <angular>7e-05</angular>
        </velocity_decay>
        <gravity>1</gravity>
        <velocity_decay/>
        <sensor name='laser_scanner' type='gpu_ray'>
          <visualize>0</visualize>
          <update_rate>20</update_rate>
          <ray>
            <scan>
              <horizontal>
                <samples>360</samples>
                <resolution>1</resolution>
                <min_angle>-3.14159</min_angle>
                <max_angle>3.14159</max_angle>
              </horizontal>
            </scan>
            <range>
              <min>0.1</min>
              <max>15</max>
              <resolution>0.1</resolution>
            </range>
          </ray>
          <plugin name='gpu_laser' filename='libgazebo_ros_gpu_laser.so'>
            <topicName>/scan</topicName>
            <frameName>laser_scanner_link</frameName>
            <robotNamespace>/</robotNamespace>
          </plugin>
          <pose frame=''>0.1397 0 0.2159 0 -0 0</pose>
        </sensor>
        <self_collide>0</self_collide>
        <enable_wind>0</enable_wind>
        <kinematic>0</kinematic>
      </link>
      <link name='back_left_wheel'>
        <pose frame=''>0 0.125 0 -1.5708 0 0</pose>
        <inertial>
          <pose frame=''>0 0 0 0 -0 0</pose>
          <mass>0.1</mass>
          <inertia>
            <ixx>9.68083e-05</ixx>
            <ixy>0</ixy>
            <ixz>0</ixz>
            <iyy>9.68083e-05</iyy>
            <iyz>0</iyz>
            <izz>0.0001568</izz>
          </inertia>
        </inertial>
        <collision name='back_left_wheel_collision'>
          <pose frame=''>0 0 0 0 -0 0</pose>
          <geometry>
            <cylinder>
              <length>0.047</length>
              <radius>0.056</radius>
            </cylinder>
          </geometry>
          <surface>
            <contact>
              <ode/>
            </contact>
            <friction>
              <ode>
                <mu>0.8</mu>
              </ode>
              <torsional>
                <ode/>
              </torsional>
            </friction>
            <bounce/>
          </surface>
          <max_contacts>10</max_contacts>
        </collision>
        <visual name='back_left_wheel_visual'>
          <pose frame=''>0 0 0 0 -0 0</pose>
          <geometry>
            <cylinder>
              <length>0.047</length>
              <radius>0.056</radius>
            </cylinder>
          </geometry>
          <material>
            <script>
              <name>Gazebo/DarkGrey</name>
              <uri>file://media/materials/scripts/gazebo.material</uri>
            </script>
          </material>
        </visual>
        <gravity>1</gravity>
        <velocity_decay/>
        <self_collide>0</self_collide>
        <enable_wind>0</enable_wind>
        <kinematic>0</kinematic>
      </link>
      <joint name='back_left_wheel_joint' type='revolute'>
        <child>back_left_wheel</child>
        <parent>base_link</parent>
        <axis>
          <xyz>0 1 0</xyz>
          <limit>
            <lower>-1e+16</lower>
            <upper>1e+16</upper>
          </limit>
          <dynamics>
            <spring_reference>0</spring_reference>
            <spring_stiffness>0</spring_stiffness>
          </dynamics>
          <use_parent_model_frame>1</use_parent_model_frame>
        </axis>
      </joint>
      <link name='back_right_wheel'>
        <pose frame=''>0 -0.125 0 -1.5708 0 0</pose>
        <inertial>
          <pose frame=''>0 0 0 0 -0 0</pose>
          <mass>0.1</mass>
          <inertia>
            <ixx>9.68083e-05</ixx>
            <ixy>0</ixy>
            <ixz>0</ixz>
            <iyy>9.68083e-05</iyy>
            <iyz>0</iyz>
            <izz>0.0001568</izz>
          </inertia>
        </inertial>
        <collision name='back_right_wheel_collision'>
          <pose frame=''>0 0 0 0 -0 0</pose>
          <geometry>
            <cylinder>
              <length>0.047</length>
              <radius>0.056</radius>
            </cylinder>
          </geometry>
          <surface>
            <contact>
              <ode/>
            </contact>
            <friction>
              <ode>
                <mu>0.8</mu>
              </ode>
              <torsional>
                <ode/>
              </torsional>
            </friction>
            <bounce/>
          </surface>
          <max_contacts>10</max_contacts>
        </collision>
        <visual name='back_right_wheel_visual'>
          <pose frame=''>0 0 0 0 -0 0</pose>
          <geometry>
            <cylinder>
              <length>0.047</length>
              <radius>0.056</radius>
            </cylinder>
          </geometry>
          <material>
            <script>
              <name>Gazebo/DarkGrey</name>
              <uri>file://media/materials/scripts/gazebo.material</uri>
            </script>
          </material>
        </visual>
        <gravity>1</gravity>
        <velocity_decay/>
        <self_collide>0</self_collide>
        <enable_wind>0</enable_wind>
        <kinematic>0</kinematic>
      </link>
      <joint name='back_right_wheel_joint' type='revolute'>
        <child>back_right_wheel</child>
        <parent>base_link</parent>
        <axis>
          <xyz>0 1 0</xyz>
          <limit>
            <lower>-1e+16</lower>
            <upper>1e+16</upper>
          </limit>
          <dynamics>
            <spring_reference>0</spring_reference>
            <spring_stiffness>0</spring_stiffness>
          </dynamics>
          <use_parent_model_frame>1</use_parent_model_frame>
        </axis>
      </joint>
      <link name='front_left_wheel_shock'>
        <pose frame=''>0.3429 0.125 0 0 -0 0</pose>
        <inertial>
          <pose frame=''>0 0 0 0 -0 0</pose>
          <mass>0.01</mass>
          <inertia>
            <ixx>0.015</ixx>
            <ixy>0</ixy>
            <ixz>0</ixz>
            <iyy>0.0375</iyy>
            <iyz>0</iyz>
            <izz>0.0375</izz>
          </inertia>
        </inertial>
        <collision name='front_left_wheel_shock_collision'>
          <pose frame=''>0 0 0.1 0 -0 0</pose>
          <geometry>
            <cylinder>
              <length>0.2</length>
              <radius>0.01</radius>
            </cylinder>
          </geometry>
          <max_contacts>10</max_contacts>
          <surface>
            <contact>
              <ode/>
            </contact>
            <bounce/>
            <friction>
              <torsional>
                <ode/>
              </torsional>
              <ode/>
            </friction>
          </surface>
        </collision>
        <visual name='front_left_wheel_shock_visual'>
          <pose frame=''>0 0 0.1 0 -0 0</pose>
          <geometry>
            <cylinder>
              <length>0.2</length>
              <radius>0.01</radius>
            </cylinder>
          </geometry>
        </visual>
        <self_collide>0</self_collide>
        <enable_wind>0</enable_wind>
        <kinematic>0</kinematic>
      </link>
      <joint name='front_left_shock_joint' type='prismatic'>
        <child>front_left_wheel_shock</child>
        <parent>base_link</parent>
        <axis>
          <xyz>0 0 1</xyz>
          <limit>
            <lower>-0.045</lower>
            <upper>0.045</upper>
            <effort>100</effort>
            <velocity>100</velocity>
          </limit>
          <dynamics>
            <spring_reference>0</spring_reference>
            <spring_stiffness>0</spring_stiffness>
          </dynamics>
          <use_parent_model_frame>1</use_parent_model_frame>
        </axis>
      </joint>
      <link name='front_left_wheel_steer'>
        <pose frame=''>0.3429 0.125 0 0 -0 0</pose>
        <inertial>
          <pose frame=''>0 0 0 0 -0 0</pose>
          <mass>0.1</mass>
          <inertia>
            <ixx>5.1458e-05</ixx>
            <ixy>0</ixy>
            <ixz>0</ixz>
            <iyy>5.1458e-05</iyy>
            <iyz>0</iyz>
            <izz>6.125e-05</izz>
          </inertia>
        </inertial>
        <collision name='front_left_wheel_steer_collision'>
          <pose frame=''>0 0 0 0 -0 0</pose>
          <geometry>
            <cylinder>
              <length>0.01</length>
              <radius>0.01</radius>
            </cylinder>
          </geometry>
          <max_contacts>10</max_contacts>
          <surface>
            <contact>
              <ode/>
            </contact>
            <bounce/>
            <friction>
              <torsional>
                <ode/>
              </torsional>
              <ode/>
            </friction>
          </surface>
        </collision>
        <visual name='front_left_wheel_steer_visual'>
          <pose frame=''>0 0 0 0 -0 0</pose>
          <geometry>
            <cylinder>
              <length>0.01</length>
              <radius>0.01</radius>
            </cylinder>
          </geometry>
        </visual>
        <self_collide>0</self_collide>
        <enable_wind>0</enable_wind>
        <kinematic>0</kinematic>
      </link>
      <joint name='front_left_wheel_steer_joint' type='revolute'>
        <child>front_left_wheel_steer</child>
        <parent>front_left_wheel_shock</parent>
        <axis>
          <xyz>0 0 1</xyz>
          <limit>
            <lower>-1</lower>
            <upper>1</upper>
            <effort>1</effort>
            <velocity>5</velocity>
          </limit>
          <dynamics>
            <spring_reference>0</spring_reference>
            <spring_stiffness>0</spring_stiffness>
          </dynamics>
          <use_parent_model_frame>1</use_parent_model_frame>
        </axis>
      </joint>
      <link name='front_left_wheel'>
        <pose frame=''>0.3429 0.125 0 -1.5708 0 0</pose>
        <inertial>
          <pose frame=''>0 0 0 0 -0 0</pose>
          <mass>0.1</mass>
          <inertia>
            <ixx>9.68083e-05</ixx>
            <ixy>0</ixy>
            <ixz>0</ixz>
            <iyy>9.68083e-05</iyy>
            <iyz>0</iyz>
            <izz>0.0001568</izz>
          </inertia>
        </inertial>
        <collision name='front_left_wheel_collision'>
          <pose frame=''>0 0 0 0 -0 0</pose>
          <geometry>
            <cylinder>
              <length>0.047</length>
              <radius>0.056</radius>
            </cylinder>
          </geometry>
          <surface>
            <contact>
              <ode/>
            </contact>
            <friction>
              <ode>
                <mu>0.8</mu>
              </ode>
              <torsional>
                <ode/>
              </torsional>
            </friction>
            <bounce/>
          </surface>
          <max_contacts>10</max_contacts>
        </collision>
        <visual name='front_left_wheel_visual'>
          <pose frame=''>0 0 0 0 -0 0</pose>
          <geometry>
            <cylinder>
              <length>0.047</length>
              <radius>0.056</radius>
            </cylinder>
          </geometry>
          <material>
            <script>
              <name>Gazebo/DarkGrey</name>
              <uri>file://media/materials/scripts/gazebo.material</uri>
            </script>
          </material>
        </visual>
        <gravity>1</gravity>
        <velocity_decay/>
        <self_collide>0</self_collide>
        <enable_wind>0</enable_wind>
        <kinematic>0</kinematic>
      </link>
      <joint name='front_left_wheel_joint' type='revolute'>
        <child>front_left_wheel</child>
        <parent>front_left_wheel_steer</parent>
        <axis>
          <xyz>0 1 0</xyz>
          <limit>
            <lower>-1e+16</lower>
            <upper>1e+16</upper>
          </limit>
          <dynamics>
            <spring_reference>0</spring_reference>
            <spring_stiffness>0</spring_stiffness>
          </dynamics>
          <use_parent_model_frame>1</use_parent_model_frame>
        </axis>
      </joint>
      <link name='front_right_wheel_shock'>
        <pose frame=''>0.3429 -0.125 0 0 -0 0</pose>
        <inertial>
          <pose frame=''>0 0 0 0 -0 0</pose>
          <mass>0.01</mass>
          <inertia>
            <ixx>0.015</ixx>
            <ixy>0</ixy>
            <ixz>0</ixz>
            <iyy>0.0375</iyy>
            <iyz>0</iyz>
            <izz>0.0375</izz>
          </inertia>
        </inertial>
        <collision name='front_right_wheel_shock_collision'>
          <pose frame=''>0 0 0.1 0 -0 0</pose>
          <geometry>
            <cylinder>
              <length>0.2</length>
              <radius>0.01</radius>
            </cylinder>
          </geometry>
          <max_contacts>10</max_contacts>
          <surface>
            <contact>
              <ode/>
            </contact>
            <bounce/>
            <friction>
              <torsional>
                <ode/>
              </torsional>
              <ode/>
            </friction>
          </surface>
        </collision>
        <visual name='front_right_wheel_shock_visual'>
          <pose frame=''>0 0 0.1 0 -0 0</pose>
          <geometry>
            <cylinder>
              <length>0.2</length>
              <radius>0.01</radius>
            </cylinder>
          </geometry>
        </visual>
        <self_collide>0</self_collide>
        <enable_wind>0</enable_wind>
        <kinematic>0</kinematic>
      </link>
      <joint name='front_right_shock_joint' type='prismatic'>
        <child>front_right_wheel_shock</child>
        <parent>base_link</parent>
        <axis>
          <xyz>0 0 1</xyz>
          <limit>
            <lower>-0.045</lower>
            <upper>0.045</upper>
            <effort>100</effort>
            <velocity>100</velocity>
          </limit>
          <dynamics>
            <spring_reference>0</spring_reference>
            <spring_stiffness>0</spring_stiffness>
          </dynamics>
          <use_parent_model_frame>1</use_parent_model_frame>
        </axis>
      </joint>
      <link name='front_right_wheel_steer'>
        <pose frame=''>0.3429 -0.125 0 0 -0 0</pose>
        <inertial>
          <pose frame=''>0 0 0 0 -0 0</pose>
          <mass>0.1</mass>
          <inertia>
            <ixx>5.1458e-05</ixx>
            <ixy>0</ixy>
            <ixz>0</ixz>
            <iyy>5.1458e-05</iyy>
            <iyz>0</iyz>
            <izz>6.125e-05</izz>
          </inertia>
        </inertial>
        <collision name='front_right_wheel_steer_collision'>
          <pose frame=''>0 0 0 0 -0 0</pose>
          <geometry>
            <cylinder>
              <length>0.01</length>
              <radius>0.01</radius>
            </cylinder>
          </geometry>
          <max_contacts>10</max_contacts>
          <surface>
            <contact>
              <ode/>
            </contact>
            <bounce/>
            <friction>
              <torsional>
                <ode/>
              </torsional>
              <ode/>
            </friction>
          </surface>
        </collision>
        <visual name='front_right_wheel_steer_visual'>
          <pose frame=''>0 0 0 0 -0 0</pose>
          <geometry>
            <cylinder>
              <length>0.01</length>
              <radius>0.01</radius>
            </cylinder>
          </geometry>
        </visual>
        <self_collide>0</self_collide>
        <enable_wind>0</enable_wind>
        <kinematic>0</kinematic>
      </link>
      <joint name='front_right_wheel_steer_joint' type='revolute'>
        <child>front_right_wheel_steer</child>
        <parent>front_right_wheel_shock</parent>
        <axis>
          <xyz>0 0 1</xyz>
          <limit>
            <lower>-1</lower>
            <upper>1</upper>
            <effort>1</effort>
            <velocity>5</velocity>
          </limit>
          <dynamics>
            <spring_reference>0</spring_reference>
            <spring_stiffness>0</spring_stiffness>
          </dynamics>
          <use_parent_model_frame>1</use_parent_model_frame>
        </axis>
      </joint>
      <link name='front_right_wheel'>
        <pose frame=''>0.3429 -0.125 0 -1.5708 0 0</pose>
        <inertial>
          <pose frame=''>0 0 0 0 -0 0</pose>
          <mass>0.1</mass>
          <inertia>
            <ixx>9.68083e-05</ixx>
            <ixy>0</ixy>
            <ixz>0</ixz>
            <iyy>9.68083e-05</iyy>
            <iyz>0</iyz>
            <izz>0.0001568</izz>
          </inertia>
        </inertial>
        <collision name='front_right_wheel_collision'>
          <pose frame=''>0 0 0 0 -0 0</pose>
          <geometry>
            <cylinder>
              <length>0.047</length>
              <radius>0.056</radius>
            </cylinder>
          </geometry>
          <surface>
            <contact>
              <ode/>
            </contact>
            <friction>
              <ode>
                <mu>0.8</mu>
              </ode>
              <torsional>
                <ode/>
              </torsional>
            </friction>
            <bounce/>
          </surface>
          <max_contacts>10</max_contacts>
        </collision>
        <visual name='front_right_wheel_visual'>
          <pose frame=''>0 0 0 0 -0 0</pose>
          <geometry>
            <cylinder>
              <length>0.047</length>
              <radius>0.056</radius>
            </cylinder>
          </geometry>
          <material>
            <script>
              <name>Gazebo/DarkGrey</name>
              <uri>file://media/materials/scripts/gazebo.material</uri>
            </script>
          </material>
        </visual>
        <gravity>1</gravity>
        <velocity_decay/>
        <self_collide>0</self_collide>
        <enable_wind>0</enable_wind>
        <kinematic>0</kinematic>
      </link>
      <joint name='front_right_wheel_joint' type='revolute'>
        <child>front_right_wheel</child>
        <parent>front_right_wheel_steer</parent>
        <axis>
          <xyz>0 1 0</xyz>
          <limit>
            <lower>-1e+16</lower>
            <upper>1e+16</upper>
          </limit>
          <dynamics>
            <spring_reference>0</spring_reference>
            <spring_stiffness>0</spring_stiffness>
          </dynamics>
          <use_parent_model_frame>1</use_parent_model_frame>
        </axis>
      </joint>
      <static>0</static>
      <plugin name='fake_car_plugin' filename='libfake_car_plugin.so'>
        <robotNamespace>/</robotNamespace>
      </plugin>
      <pose frame=''>0 0 0 0 -0 0</pose>
    </model>
    <model name='unit_box'>
      <pose frame=''>1.48678 -2.50036 0.5 0 -0 0</pose>
      <link name='link'>
        <inertial>
          <mass>1</mass>
          <inertia>
            <ixx>0.166667</ixx>
            <ixy>0</ixy>
            <ixz>0</ixz>
            <iyy>0.166667</iyy>
            <iyz>0</iyz>
            <izz>0.166667</izz>
          </inertia>
        </inertial>
        <collision name='collision'>
          <geometry>
            <box>
              <size>1 1 0.999979</size>
            </box>
          </geometry>
          <max_contacts>10</max_contacts>
          <surface>
            <contact>
              <ode/>
            </contact>
            <bounce/>
            <friction>
              <torsional>
                <ode/>
              </torsional>
              <ode/>
            </friction>
          </surface>
        </collision>
        <visual name='visual'>
          <geometry>
            <box>
              <size>1 1 0.999979</size>
            </box>
          </geometry>
          <material>
            <script>
              <name>Gazebo/Grey</name>
              <uri>file://media/materials/scripts/gazebo.material</uri>
            </script>
          </material>
        </visual>
        <self_collide>0</self_collide>
        <enable_wind>0</enable_wind>
        <kinematic>0</kinematic>
      </link>
    </model>
    <model name='unit_box_clone'>
      <pose frame=''>0.915597 -0.148789 0.005865 9.3e-05 2e-06 -7e-06</pose>
      <link name='link'>
        <inertial>
          <mass>1</mass>
          <inertia>
            <ixx>0.166667</ixx>
            <ixy>0</ixy>
            <ixz>0</ixz>
            <iyy>0.166667</iyy>
            <iyz>0</iyz>
            <izz>0.166667</izz>
          </inertia>
        </inertial>
        <collision name='collision'>
          <geometry>
            <box>
              <size>0.119833 2.15042 0.011929</size>
            </box>
          </geometry>
          <max_contacts>10</max_contacts>
          <surface>
            <contact>
              <ode/>
            </contact>
            <bounce/>
            <friction>
              <torsional>
                <ode/>
              </torsional>
              <ode/>
            </friction>
          </surface>
        </collision>
        <visual name='visual'>
          <geometry>
            <box>
              <size>0.119833 2.15042 0.011929</size>
            </box>
          </geometry>
          <material>
            <script>
              <name>Gazebo/Grey</name>
              <uri>file://media/materials/scripts/gazebo.material</uri>
            </script>
          </material>
        </visual>
        <self_collide>0</self_collide>
        <enable_wind>0</enable_wind>
        <kinematic>0</kinematic>
      </link>
    </model>
    <model name='unit_box_clone_0'>
      <pose frame=''>1.27133 -0.203897 0.005865 9.3e-05 2e-06 -7e-06</pose>
      <link name='link'>
        <inertial>
          <mass>1</mass>
          <inertia>
            <ixx>0.166667</ixx>
            <ixy>0</ixy>
            <ixz>0</ixz>
            <iyy>0.166667</iyy>
            <iyz>0</iyz>
            <izz>0.166667</izz>
          </inertia>
        </inertial>
        <collision name='collision'>
          <geometry>
            <box>
              <size>0.119833 2.15042 0.011929</size>
            </box>
          </geometry>
          <max_contacts>10</max_contacts>
          <surface>
            <contact>
              <ode/>
            </contact>
            <bounce/>
            <friction>
              <torsional>
                <ode/>
              </torsional>
              <ode/>
            </friction>
          </surface>
        </collision>
        <visual name='visual'>
          <geometry>
            <box>
              <size>0.119833 2.15042 0.011929</size>
            </box>
          </geometry>
          <material>
            <script>
              <name>Gazebo/Grey</name>
              <uri>file://media/materials/scripts/gazebo.material</uri>
            </script>
          </material>
        </visual>
        <self_collide>0</self_collide>
        <enable_wind>0</enable_wind>
        <kinematic>0</kinematic>
      </link>
    </model>
    <model name='unit_box_clone_1'>
      <pose frame=''>1.58524 -0.13212 0.005865 9.3e-05 2e-06 -7e-06</pose>
      <link name='link'>
        <inertial>
          <mass>1</mass>
          <inertia>
            <ixx>0.166667</ixx>
            <ixy>0</ixy>
            <ixz>0</ixz>
            <iyy>0.166667</iyy>
            <iyz>0</iyz>
            <izz>0.166667</izz>
          </inertia>
        </inertial>
        <collision name='collision'>
          <geometry>
            <box>
              <size>0.119833 2.15042 0.011929</size>
            </box>
          </geometry>
          <max_contacts>10</max_contacts>
          <surface>
            <contact>
              <ode/>
            </contact>
            <bounce/>
            <friction>
              <torsional>
                <ode/>
              </torsional>
              <ode/>
            </friction>
          </surface>
        </collision>
        <visual name='visual'>
          <geometry>
            <box>
              <size>0.119833 2.15042 0.011929</size>
            </box>
          </geometry>
          <material>
            <script>
              <name>Gazebo/Grey</name>
              <uri>file://media/materials/scripts/gazebo.material</uri>
            </script>
          </material>
        </visual>
        <self_collide>0</self_collide>
        <enable_wind>0</enable_wind>
        <kinematic>0</kinematic>
      </link>
    </model>
    <model name='unit_box_clone_2'>
      <pose frame=''>1.97698 -0.206336 0.005865 9.3e-05 2e-06 -7e-06</pose>
      <link name='link'>
        <inertial>
          <mass>1</mass>
          <inertia>
            <ixx>0.166667</ixx>
            <ixy>0</ixy>
            <ixz>0</ixz>
            <iyy>0.166667</iyy>
            <iyz>0</iyz>
            <izz>0.166667</izz>
          </inertia>
        </inertial>
        <collision name='collision'>
          <geometry>
            <box>
              <size>0.119833 2.15042 0.011929</size>
            </box>
          </geometry>
          <max_contacts>10</max_contacts>
          <surface>
            <contact>
              <ode/>
            </contact>
            <bounce/>
            <friction>
              <torsional>
                <ode/>
              </torsional>
              <ode/>
            </friction>
          </surface>
        </collision>
        <visual name='visual'>
          <geometry>
            <box>
              <size>0.119833 2.15042 0.011929</size>
            </box>
          </geometry>
          <material>
            <script>
              <name>Gazebo/Grey</name>
              <uri>file://media/materials/scripts/gazebo.material</uri>
            </script>
          </material>
        </visual>
        <self_collide>0</self_collide>
        <enable_wind>0</enable_wind>
        <kinematic>0</kinematic>
      </link>
    </model>
    <state world_name='default'>
      <sim_time>109 285000000</sim_time>
      <real_time>110 104996753</real_time>
      <wall_time>1547431331 476428994</wall_time>
      <iterations>109285</iterations>
      <model name='fake_car'>
        <pose frame=''>1.47574 -0.863116 0.056 0 0.018706 -0.105765</pose>
        <scale>1 1 1</scale>
        <link name='back_left_wheel'>
          <pose frame=''>1.48893 -0.738815 0.056 -1.57083 -0.670713 -0.105747</pose>
          <velocity>-0.000107 5.3e-05 -1e-06 -0.000851 -0.002116 0.000488</velocity>
          <acceleration>-0.09238 0.049244 -0.003844 -0.797901 -1.03365 0.573786</acceleration>
          <wrench>-0.009238 0.004924 -0.000384 0 -0 0</wrench>
        </link>
        <link name='back_right_wheel'>
          <pose frame=''>1.46254 -0.987418 0.056 -1.57078 0.696339 -0.10575</pose>
          <velocity>1.2e-05 3.8e-05 -1e-06 -0.000709 0.000416 0.000494</velocity>
          <acceleration>-0.009433 0.040722 0.00383 -0.705282 -0.117849 0.566269</acceleration>
          <wrench>-0.000943 0.004072 0.000383 0 -0 0</wrench>
        </link>
        <link name='base_link'>
          <pose frame=''>1.47574 -0.863116 0.056 0 0.018706 -0.105765</pose>
          <velocity>-4.6e-05 6.1e-05 -1e-06 -9.7e-05 -2.4e-05 0.000475</velocity>
          <acceleration>-0.038497 0.122378 -0.012702 -2.26086 0.22177 0.346558</acceleration>
          <wrench>-0.100476 0.319406 -0.033152 0 -0 0</wrench>
        </link>
        <link name='front_left_wheel'>
          <pose frame=''>1.82998 -0.775021 0.056 -1.5708 0.118876 -0.105214</pose>
          <velocity>-6.7e-05 0.000118 1.1e-05 -0.002103 -0.00121 -0.00012</velocity>
          <acceleration>-0.214975 0.099043 -9.98819 1.53412 -0.825535 3.12117</acceleration>
          <wrench>-0.021498 0.009904 -0.998819 0 -0 0</wrench>
        </link>
        <link name='front_left_wheel_shock'>
          <pose frame=''>1.82998 -0.775021 0.056 0 0.018706 -0.105765</pose>
          <velocity>-5.8e-05 0.000118 1.1e-05 -0.000112 -2.2e-05 0.000471</velocity>
          <acceleration>-0.197884 0.100155 -9.98844 0.406024 1.17492 -2.48389</acceleration>
          <wrench>-0.001979 0.001002 -0.099884 0 -0 0</wrench>
        </link>
        <link name='front_left_wheel_steer'>
          <pose frame=''>1.82998 -0.775021 0.056 4e-06 0.018706 -0.105215</pose>
          <velocity>-6.6e-05 0.000139 1.1e-05 -0.001028 7.5e-05 -0.000274</velocity>
          <acceleration>-0.215159 0.118509 -9.98813 -0.612693 0.139313 0.057377</acceleration>
          <wrench>-0.021516 0.011851 -0.998812 0 -0 0</wrench>
        </link>
        <link name='front_right_wheel'>
          <pose frame=''>1.80359 -1.02362 0.056 -1.5708 0.867175 -0.105613</pose>
          <velocity>0.000176 9.3e-05 0.010002 -0.001669 0.00314 5e-06</velocity>
          <acceleration>0.888821 -0.067168 50.3311 1.3677 -1.43106 2.27539</acceleration>
          <wrench>0.088882 -0.006717 5.03311 0 -0 0</wrench>
        </link>
        <link name='front_right_wheel_shock'>
          <pose frame=''>1.80359 -1.02362 0.056 0 0.018706 -0.105765</pose>
          <velocity>0.00023 0.000228 0.010002 -0.000102 -2.2e-05 0.000474</velocity>
          <acceleration>0.958212 0.109977 50.3302 -2.167 -1.46729 0.051805</acceleration>
          <wrench>0.009582 0.0011 0.503302 0 -0 0</wrench>
        </link>
        <link name='front_right_wheel_steer'>
          <pose frame=''>1.80359 -1.02362 0.056 4e-06 0.018706 -0.105613</pose>
          <velocity>0.000185 0.000131 0.010003 0.000129 -4.7e-05 -1.5e-05</velocity>
          <acceleration>0.898541 -0.021664 50.331 -0.016381 0.077294 -2.01238</acceleration>
          <wrench>0.089854 -0.002166 5.0331 0 -0 0</wrench>
        </link>
      </model>
      <model name='ground_plane'>
        <pose frame=''>0 0 0 0 -0 0</pose>
        <scale>1 1 1</scale>
        <link name='link'>
          <pose frame=''>0 0 0 0 -0 0</pose>
          <velocity>0 0 0 0 -0 0</velocity>
          <acceleration>0 0 0 0 -0 0</acceleration>
          <wrench>0 0 0 0 -0 0</wrench>
        </link>
      </model>
      <model name='unit_box'>
        <pose frame=''>0.603229 -0.089784 0.005965 0 -0 0.002633</pose>
        <scale>0.119833 2.15042 0.011929</scale>
        <link name='link'>
          <pose frame=''>0.603229 -0.089784 0.005965 0 -0 0.002633</pose>
          <velocity>0 0 0 0 -0 0</velocity>
          <acceleration>-0.030665 0.057019 9.91179 3.00931 1.22243 5.1e-05</acceleration>
          <wrench>-0.030665 0.057019 9.91179 0 -0 0</wrench>
        </link>
      </model>
      <model name='unit_box_clone'>
        <pose frame=''>0.912878 -0.148895 0.00596 -5e-06 3e-06 0.004076</pose>
        <scale>1 1 1</scale>
        <link name='link'>
          <pose frame=''>0.912878 -0.148895 0.00596 -5e-06 3e-06 0.004076</pose>
          <velocity>0 0 0 0 -0 0</velocity>
          <acceleration>-0.002994 0.049531 -8.51252 -2.01896 -0.496592 -0.000201</acceleration>
          <wrench>-0.002994 0.049531 -8.51252 0 -0 0</wrench>
        </link>
      </model>
      <model name='unit_box_clone_0'>
        <pose frame=''>1.27617 -0.203722 0.005964 0 6e-06 0.003901</pose>
        <scale>1 1 1</scale>
        <link name='link'>
          <pose frame=''>1.27617 -0.203722 0.005964 0 6e-06 0.003901</pose>
          <velocity>0 0 0 0 -0 0</velocity>
          <acceleration>0.020565 8e-05 -0.206597 3.12814 -0.306456 -3.14159</acceleration>
          <wrench>0.020565 8e-05 -0.206597 0 -0 0</wrench>
        </link>
      </model>
      <model name='unit_box_clone_1'>
        <pose frame=''>1.5804 -0.131004 0.003348 0.007063 -0.000726 0.000728</pose>
        <scale>1 1 1</scale>
        <link name='link'>
          <pose frame=''>1.5804 -0.131004 0.003348 0.007063 -0.000726 0.000728</pose>
          <velocity>0 0 0 0 -0 0</velocity>
          <acceleration>0 -0 -9.8 -0 -0 -0</acceleration>
          <wrench>0 -0 -9.8 0 -0 0</wrench>
        </link>
      </model>
      <model name='unit_box_clone_2'>
        <pose frame=''>1.98588 -0.205484 0.005865 9.3e-05 -2e-06 0.004382</pose>
        <scale>1 1 1</scale>
        <link name='link'>
          <pose frame=''>1.98588 -0.205484 0.005865 9.3e-05 -2e-06 0.004382</pose>
          <velocity>0 0 0 0 -0 0</velocity>
          <acceleration>-0.005208 -0.383364 -0 0.382 -1.14243 -0</acceleration>
          <wrench>-0.005208 -0.383364 -0 0 -0 0</wrench>
        </link>
      </model>
      <light name='sun'>
        <pose frame=''>0 0 10 0 -0 0</pose>
      </light>
    </state>
    <gui fullscreen='0'>
      <camera name='user_camera'>
        <pose frame=''>5 -5 2 0 0.275643 2.35619</pose>
        <view_controller>orbit</view_controller>
        <projection_type>perspective</projection_type>
      </camera>
    </gui>
  </world>
</sdf>
