<?xml version="1.0" ?>
<sdf version="1.4">
  <world name="default">
    <include>
      <uri>model://ground_plane</uri>
    </include>

    <include>
      <uri>model://sun</uri>
    </include>

    <!-- reference to your plugin -->
    <model name="fake_car">
        <link name='chassis'>
            <pose>0 0 .1 0 0 0</pose>

            <collision name='collision'>
              <geometry>
                <box>
                  <size>.4 .2 .1</size>
                </box>
              </geometry>
            </collision>

            <visual name='visual'>
              <geometry>
                <box>
                  <size>.4 .2 .1</size>
                </box>
              </geometry>
            </visual>
          </link>
          <link name='bar'>
					<pose>0 0 .1 0 0 0</pose>
            <collision name='collisionbar'>
              <geometry>
                <box>
                  <size>1 .1 .1</size>
                </box>
              </geometry>
            </collision>

            <visual name='visualbar'>
              <geometry>
                <box>
                  <size>1 .1 .1</size>
                </box>
              </geometry>
            </visual>
          </link>

        <joint name="bar_joint" type="revolute">
          <parent>chassis</parent>
        	<child>bar</child>
        	<pose>0 0.5 0 0 0 0</pose>
        	<axis>
            <xyz>0 0 1</xyz>
        	</axis>
        </joint>


      <!-- Attach the plugin to this model -->
      <plugin name="fake_car_plugin" filename="libfake_car_plugin.so"/>
    </model>

  </world>
</sdf>